Workbook

Sheet Clientes
A1: ID_Cliente | B1: Nome_Cliente | C1: Cidade | D1: Estado | E1: Tipo_Cliente
A2: 1 | B2: Mariana Oliveira | C2: São Paulo | D2: SP | E2: Pessoa Física
A3: 2 | B3: Rafael Mendes | C3: Santo André | D3: SP | E3: Pessoa Jurídica
A4: 3 | B4: Camila Ferreira | C4: Mauá | D4: SP | E4: Pessoa Física
A5: 4 | B5: Lucas Almeida | C5: São Bernardo do Campo | D5: SP | E5: Pessoa Jurídica
A6: 5 | B6: Beatriz Carvalho | C6: Guarulhos | D6: SP | E6: Pessoa Física
A7: 6 | B7: Gustavo Martins | C7: Osasco | D7: SP | E7: Pessoa Jurídica
A8: 7 | B8: Juliana Rocha | C8: Mogi das Cruzes | D8: SP | E8: Pessoa Física
A9: 8 | B9: Thiago Barbosa | C9: Santos | D9: SP | E9: Pessoa Jurídica
A10: 9 | B10: Larissa Costa | C10: Campinas | D10: SP | E10: Pessoa Física
A11: 10 | B11: Pedro Nascimento | C11: Sorocaba | D11: SP | E11: Pessoa Jurídica
A12: 11 | B12: Fernanda Souza | C12: Jundiaí | D12: SP | E12: Pessoa Física
A13: 12 | B13: André Ribeiro | C13: Diadema | D13: SP | E13: Pessoa Jurídica
... A101: 100 | B101: Pedro Nascimento | C101: Sorocaba | D101: SP | E101: Pessoa Jurídica

Sheet Produtos
A1: ID_Produto | B1: Produto | C1: Categoria | D1: Preco_Unitario
A2: 101 | B2: Notebook | C2: Informática | D2: 3500
A3: 102 | B3: Monitor | C3: Informática | D3: 1200
A4: 103 | B4: Teclado | C4: Informática | D4: 180
A5: 104 | B5: Mouse | C5: Informática | D5: 90
A6: 105 | B6: Cadeira Escritório | C6: Móveis | D6: 850
A7: 106 | B7: Mesa Escritório | C7: Móveis | D7: 1100
A8: 107 | B8: Fone de Ouvido | C8: Eletrônicos | D8: 250
A9: 108 | B9: Smartphone | C9: Eletrônicos | D9: 2200
A10: 109 | B10: Impressora | C10: Informática | D10: 950
A11: 110 | B11: Mochila | C11: Acessórios | D11: 160
A12: 111 | B12: Webcam | C12: Informática | D12: 320
A13: 112 | B13: Headset | C13: Eletrônicos | D13: 420
... A101: 200 | B101: Mochila | C101: Acessórios | D101: 179.2

Sheet Pedidos
A1: ID_Pedido | B1: ID_Cliente | C1: ID_Produto | D1: Data_Pedido | E1: Quantidade | F1: Canal_Venda | G1: Status | H1: Preco_Unitario | I1: Desconto | J1: Valor_Bruto | K1: Valor_Liquido | L1: Produtos | M1: Categoria | N1: Cidade de Clientes
A2: 1001 | B2: 9 | C2: 152 | D2: 46023 | E2: 2 | F2: Marketplace | G2: Entregue | H2: 728 | I2: 0 | J2: 1456 | K2: 1456 | L2: =VLOOKUP(C2,Produtos!$A$1:$D$101,2,FALSE) -> Nobreak | M2: =VLOOKUP(C2,Produtos!$A$1:$D$101,3,FALSE) -> Informática | N2: =VLOOKUP(B2,Clientes!$A$1:$E$101,3,FALSE) -> Campinas
A3: 1002 | B3: 62 | C3: 193 | D3: 46024 | E3: 1 | F3: Marketplace | G3: Entregue | H3: 201.6 | I3: 0 | J3: 201.6 | K3: 201.6 | L3: =VLOOKUP(C3,Produtos!$A$1:$D$101,2,FALSE) -> Teclado | M3: =VLOOKUP(C3,Produtos!$A$1:$D$101,3,FALSE) -> Informática | N3: =VLOOKUP(B3,Clientes!$A$1:$E$101,3,FALSE) -> Santo André
A4: 1003 | B4: 37 | C4: 115 | D4: 46026 | E4: 1 | F4: Loja Física | G4: Em transporte | H4: 500 | I4: 0 | J4: 500 | K4: 500 | L4: =VLOOKUP(C4,Produtos!$A$1:$D$101,2,FALSE) -> SSD | M4: =VLOOKUP(C4,Produtos!$A$1:$D$101,3,FALSE) -> Informática | N4: =VLOOKUP(B4,Clientes!$A$1:$E$101,3,FALSE) -> Mogi das Cruzes
A5: 1004 | B5: 97 | C5: 172 | D5: 46027 | E5: 1 | F5: Site | G5: Em transporte | H5: 453.6 | I5: 0.05 | J5: 453.6 | K5: 430.92 | L5: =VLOOKUP(C5,Produtos!$A$1:$D$101,2,FALSE) -> Headset | M5: =VLOOKUP(C5,Produtos!$A$1:$D$101,3,FALSE) -> Eletrônicos | N5: =VLOOKUP(B5,Clientes!$A$1:$E$101,3,FALSE) -> Mogi das Cruzes
A6: 1005 | B6: 51 | C6: 161 | D6: 46029 | E6: 1 | F6: Site | G6: Entregue | H6: 3780 | I6: 0 | J6: 3780 | K6: 3780 | L6: =VLOOKUP(C6,Produtos!$A$1:$D$101,2,FALSE) -> Notebook | M6: =VLOOKUP(C6,Produtos!$A$1:$D$101,3,FALSE) -> Informática | N6: =VLOOKUP(B6,Clientes!$A$1:$E$101,3,FALSE) -> Osasco
A7: 1006 | B7: 44 | C7: 121 | D7: 46030 | E7: 1 | F7: Loja Física | G7: Em transporte | H7: 260 | I7: 0 | J7: 260 | K7: 260 | L7: =VLOOKUP(C7,Produtos!$A$1:$D$101,2,FALSE) -> Estabilizador | M7: =VLOOKUP(C7,Produtos!$A$1:$D$101,3,FALSE) -> Informática | N7: =VLOOKUP(B7,Clientes!$A$1:$E$101,3,FALSE) -> Piracicaba
A8: 1007 | B8: 24 | C8: 183 | D8: 46032 | E8: 1 | F8: Site | G8: Entregue | H8: 1566 | I8: 0.1 | J8: 1566 | K8: 1409.4 | L8: =VLOOKUP(C8,Produtos!$A$1:$D$101,2,FALSE) -> Cadeira Gamer | M8: =VLOOKUP(C8,Produtos!$A$1:$D$101,3,FALSE) -> Móveis | N8: =VLOOKUP(B8,Clientes!$A$1:$E$101,3,FALSE) -> Campinas
A9: 1008 | B9: 79 | C9: 187 | D9: 46033 | E9: 1 | F9: Loja Física | G9: Entregue | H9: 75.6 | I9: 0.1 | J9: 75.6 | K9: 68.04 | L9: =VLOOKUP(C9,Produtos!$A$1:$D$101,2,FALSE) -> Pen Drive | M9: =VLOOKUP(C9,Produtos!$A$1:$D$101,3,FALSE) -> Informática | N9: =VLOOKUP(B9,Clientes!$A$1:$E$101,3,FALSE) -> São Bernardo do Campo
A10: 1009 | B10: 59 | C10: 175 | D10: 46035 | E10: 1 | F10: Site | G10: Em transporte | H10: 540 | I10: 0 | J10: 540 | K10: 540 | L10: =VLOOKUP(C10,Produtos!$A$1:$D$101,2,FALSE) -> SSD | M10: =VLOOKUP(C10,Produtos!$A$1:$D$101,3,FALSE) -> Informática | N10: =VLOOKUP(B10,Clientes!$A$1:$E$101,3,FALSE) -> Piracicaba
A11: 1010 | B11: 32 | C11: 175 | D11: 46036 | E11: 3 | F11: Loja Física | G11: Em transporte | H11: 540 | I11: 0 | J11: 1620 | K11: 1620 | L11: =VLOOKUP(C11,Produtos!$A$1:$D$101,2,FALSE) -> SSD | M11: =VLOOKUP(C11,Produtos!$A$1:$D$101,3,FALSE) -> Informática | N11: =VLOOKUP(B11,Clientes!$A$1:$E$101,3,FALSE) -> Santo André
A12: 1011 | B12: 96 | C12: 188 | D12: 46038 | E12: 1 | F12: Site | G12: Em transporte | H12: 118.8 | I12: 0.05 | J12: 118.8 | K12: 112.86 | L12: =VLOOKUP(C12,Produtos!$A$1:$D$101,2,FALSE) -> Carregador | M12: =VLOOKUP(C12,Produtos!$A$1:$D$101,3,FALSE) -> Eletrônicos | N12: =VLOOKUP(B12,Clientes!$A$1:$E$101,3,FALSE) -> Osasco
A13: 1012 | B13: 88 | C13: 200 | D13: 46039 | E13: 2 | F13: Loja Física | G13: Cancelado | H13: 179.2 | I13: 0 | J13: 358.4 | K13: 358.4 | L13: =VLOOKUP(C13,Produtos!$A$1:$D$101,2,FALSE) -> Mochila | M13: =VLOOKUP(C13,Produtos!$A$1:$D$101,3,FALSE) -> Acessórios | N13: =VLOOKUP(B13,Clientes!$A$1:$E$101,3,FALSE) -> Bauru
... A201: 1200 | B201: 23 | C201: 127 | D201: 46321 | E201: 1 | F201: Loja Física | G201: Entregue | H201: 70 | I201: 0.15 | J201: 70 | K201: 59.5 | L201: =VLOOKUP(C201,Produtos!$A$1:$D$101,2,FALSE) -> Pen Drive | M201: =VLOOKUP(C201,Produtos!$A$1:$D$101,3,FALSE) -> Informática | N201: =VLOOKUP(B201,Clientes!$A$1:$E$101,3,FALSE) -> Santos

Sheet Devolucoes
A1: ID_Devolucao | B1: ID_Pedido | C1: Data_Devolucao | D1: Motivo | E1: Quantidade_Devolvida | F1: Status_Devolucao
A2: 1 | B2: 1094 | C2: 46169 | D2: Produto com defeito | E2: 1 | F2: Estornado
A3: 2 | B3: 1159 | C3: 46268 | D3: Produto danificado no transporte | E3: 2 | F3: Em análise
A4: 3 | B4: 1001 | C4: 46032 | D4: Cliente desistiu da compra | E4: 1 | F4: Concluído
A5: 4 | B5: 1139 | C5: 46240 | D5: Produto diferente do esperado | E5: 2 | F5: Estornado
A6: 5 | B6: 1068 | C6: 46134 | D6: Embalagem danificada | E6: 1 | F6: Em análise
A7: 6 | B7: 1138 | C7: 46240 | D7: Produto com defeito | E7: 2 | F7: Concluído
A8: 7 | B8: 1169 | C8: 46288 | D8: Produto danificado no transporte | E8: 1 | F8: Estornado
A9: 8 | B9: 1016 | C9: 46059 | D9: Cliente desistiu da compra | E9: 2 | F9: Em análise
A10: 9 | B10: 1163 | C10: 46273 | D10: Produto diferente do esperado | E10: 1 | F10: Concluído
A11: 10 | B11: 1084 | C11: 46155 | D11: Embalagem danificada | E11: 2 | F11: Estornado
A12: 11 | B12: 1143 | C12: 46245 | D12: Produto com defeito | E12: 1 | F12: Em análise
A13: 12 | B13: 1022 | C13: 46064 | D13: Produto danificado no transporte | E13: 2 | F13: Concluído
... A41: 40 | B41: 1124 | C41: 46221 | D41: Embalagem danificada | E41: 2 | F41: Estornado

Sheet Validação Questões
A1: Status | B1: Entregue | D1: Soma de ID_Pedido | E1: Status da Venda | J1: Status | K1: Entregue | M1: Vendas por Cidades | P1: QTD Vendas Retornadas
D2: Meses | E2: Cancelado | F2: Em transporte | G2: Entregue | H2: Total Geral | J2: Faturamento por Produtos | M2: Cidades | N2: QTD ID_Pedidos | P2: Vendas Retornadas | Q2: Status
A3: ID_PEDIDO | B3: Valor_Liquido | D3: jan | E3: 1012 | F3: 10112 | G3: 10107 | H3: 21231 | J3: Produtos | K3: Valor_Liquido | M3: Campinas | N3: 25 | P3: Resumo | Q3: Concluído | R3: Em análise | S3: Estornado | T3: Total Geral | U3: Média de Devolução
A4: 1113 | B4: 7000 | D4: fev | F4: 2066 | G4: 17523 | H4: 19589 | J4: Informática | K4: 84923.96 | M4: Mogi das Cruzes | N4: 21 | P4: Cliente desistiu da compra | Q4: 3 | R4: 3 | S4: 2 | T4: 8
A5: 1119 | B5: 4400 | D5: mar | E5: 2096 | F5: 4203 | G5: 14711 | H5: 21010 | J5: Móveis | K5: 31395.4 | M5: Mauá | N5: 21 | P5: Embalagem danificada | Q5: 2 | R5: 3 | S5: 3 | T5: 8
A6: 1005 | B6: 3780 | D6: abr | E6: 1063 | F6: 4285 | G6: 16062 | H6: 21410 | J6: Eletrônicos | K6: 30322.4 | M6: Santo André | N6: 20 | P6: Produto com defeito | Q6: 3 | R6: 2 | S6: 3 | T6: 8
A7: 1167 | B7: 3744 | D7: mai | E7: 1097 | F7: 1090 | G7: 20724 | H7: 22911 | J7: Acessórios | K7: 2355.8 | M7: Santos | N7: 13 | P7: Produto danificado no transporte | Q7: 2 | R7: 3 | S7: 3 | T7: 8
A8: 1049 | B8: 3693.6 | D8: jun | E8: 3314 | F8: 2232 | G8: 16684 | H8: 22230 | J8: Total Geral | K8: 148997.56 | M8: São Paulo | N8: 12 | P8: Produto diferente do esperado | Q8: 3 | R8: 2 | S8: 3 | T8: 8
A9: 1056 | B9: 3420 | D9: jul | E9: 3403 | F9: 11308 | G9: 9061 | H9: 23772 | M9: Guarulhos | N9: 12 | P9: Total Geral | Q9: 13 | R9: 13 | S9: 14 | T9: 40 | U9: =AVERAGE(T4:T8) -> 8
A10: 1074 | B10: 3300 | D10: ago | E10: 3448 | F10: 4621 | G10: 14981 | H10: 23050 | M10: Osasco | N10: 12
A11: 1059 | B11: 3240 | D11: set | E11: 1180 | F11: 5863 | G11: 16407 | H11: 23450 | J11: Status de Entrega | M11: Piracicaba | N11: 11
A12: 1058 | B12: 3016 | D12: out | E12: 3561 | F12: 3558 | G12: 14328 | H12: 21447 | J12: Produtos | K12: QTD ID_Pedidos | M12: São Bernardo do Campo | N12: 11
A13: 1193 | B13: 2975 | D13: Total Geral | E13: 20174 | F13: 49338 | G13: 150588 | H13: 220100 | J13: Cancelado | K13: 18 | M13: São José dos Campos | N13: 10
A14: 1152 | B14: 2850 | J14: Em transporte | K14: 45 | M14: Diadema | N14: 9
A15: 1108 | B15: 2754 | J15: Entregue | K15: 137 | M15: Sorocaba | N15: 9
A16: 1034 | B16: 2688 | J16: Total Geral | K16: 200 | M16: Jundiaí | N16: 9
A17: 1149 | B17: 2592 | M17: Bauru | N17: 5
A18: 1039 | B18: 2592 | M18: Total Geral | N18: 200
A19: 1094 | B19: 2592 | J19: Periodo | K19: (Tudo)
A20: 1187 | B20: 2332.8 | J20: Pedidos por Periodo
A21: 1065 | B21: 2200 | J21: Produtos | K21: Contagem de ID_Pedido
A22: 1114 | B22: 2200 | J22: jan | K22: 21
A23: 1020 | B23: 2173.6 | J23: fev | K23: 19
A24: 1050 | B24: 1976 | J24: mar | K24: 20
A25: 1054 | B25: 1872 | J25: abr | K25: 20
A26: 1088 | B26: 1808.8 | J26: mai | K26: 21
A27: 1023 | B27: 1778.4 | J27: jun | K27: 20
A28: 1120 | B28: 1679.6 | J28: jul | K28: 21
A29: 1141 | B29: 1591.2 | J29: ago | K29: 20
A30: 1099 | B30: 1508 | J30: set | K30: 20
A31: 1084 | B31: 1458 | D31: Status | E31: Entregue | J31: out | K31: 18
A32: 1001 | B32: 1456 | D32: Faturamento Canais | J32: Total Geral | K32: 200
A33: 1133 | B33: 1450 | D33: Canais de Venda | E33: Valor Liquido
A34: 1098 | B34: 1436.4 | D34: Loja Física | E34: 31496.82
A35: 1016 | B35: 1432.6 | D35: Marketplace | E35: 40936.78
A36: 1007 | B36: 1409.4 | D36: Site | E36: 76563.96
A37: 1102 | B37: 1404 | D37: Total Geral | E37: 148997.56
A38: 1190 | B38: 1404
A39: 1077 | B39: 1352
A40: 1055 | B40: 1350
...

Sheet Relacionamentos
A1: Tabela_Origem | B1: Campo_Origem | C1: Cardinalidade | D1: Tabela_Destino | E1: Campo_Destino
A2: clientes | B2: ID_Cliente | C2: 1:N | D2: pedidos | E2: ID_Cliente
A3: produtos | B3: ID_Produto | C3: 1:N | D3: pedidos | E3: ID_Produto
A4: pedidos | B4: ID_Pedido | C4: 1:N | D4: devolucoes | E4: ID_Pedido
